<?xml version="1.0" ?>
<!-- =================================================================================== -->
<!-- |    This document was autogenerated by xacro from /home/s/practice/motoman_gazebo/src/motoman_gp7_support/urdf/gp7.xacro | -->
<!-- |    EDITING THIS FILE BY HAND IS NOT RECOMMENDED                                 | -->
<!-- =================================================================================== -->
<robot name="motoman_gp7" xmlns:xacro="http://ros.org/wiki/xacro">
    <!-- Properties -->
    <material name="yaskawa_blue">
        <color rgba="0.12941 0.14902 0.74902 1" />
    </material>
    <!-- link list -->
    <link name="base_link">
        <visual>
            <geometry>
                <mesh filename="package://motoman_gp7_support/meshes/visual/gp7_base_link.stl" />
            </geometry>
            <material name="yaskawa_blue" />
        </visual>
        <collision>
            <geometry>
                <mesh filename="package://motoman_gp7_support/meshes/collision/gp7_base_link.stl" />
            </geometry>
        </collision>
        
<inertial>
            <mass value="0.1" />
            <inertia ixx="0.03" iyy="0.03" izz="0.03" ixy="0.0" ixz="0.0" iyz="0.0" />
        </inertial>

    </link>
    <link name="link_1_s">
        <visual>
            <geometry>
                <mesh filename="package://motoman_gp7_support/meshes/visual/gp7_link_1_s.stl" />
            </geometry>
            <material name="yaskawa_blue" />
        </visual>
        <collision>
            <geometry>
                <mesh filename="package://motoman_gp7_support/meshes/collision/gp7_link_1_s.stl" />
            </geometry>
        </collision>
        
<inertial>
            <mass value="0.1" />
            <inertia ixx="0.03" iyy="0.03" izz="0.03" ixy="0.0" ixz="0.0" iyz="0.0" />
        </inertial>

    </link>
    <link name="link_2_l">
        <visual>
            <geometry>
                <mesh filename="package://motoman_gp7_support/meshes/visual/gp7_link_2_l.stl" />
            </geometry>
            <material name="yaskawa_blue" />
        </visual>
        <collision>
            <geometry>
                <mesh filename="package://motoman_gp7_support/meshes/collision/gp7_link_2_l.stl" />
            </geometry>
        </collision>
        
<inertial>
            <mass value="0.1" />
            <inertia ixx="0.03" iyy="0.03" izz="0.03" ixy="0.0" ixz="0.0" iyz="0.0" />
        </inertial>

    </link>
    <link name="link_3_u">
        <visual>
            <geometry>
                <mesh filename="package://motoman_gp7_support/meshes/visual/gp7_link_3_u.stl" />
            </geometry>
            <material name="yaskawa_blue" />
        </visual>
        <collision>
            <geometry>
                <mesh filename="package://motoman_gp7_support/meshes/collision/gp7_link_3_u.stl" />
            </geometry>
        </collision>
        
<inertial>
            <mass value="0.1" />
            <inertia ixx="0.03" iyy="0.03" izz="0.03" ixy="0.0" ixz="0.0" iyz="0.0" />
        </inertial>

    </link>
    <link name="link_4_r">
        <visual>
            <geometry>
                <mesh filename="package://motoman_gp7_support/meshes/visual/gp7_link_4_r.stl" />
            </geometry>
            <material name="yaskawa_blue" />
        </visual>
        <collision>
            <geometry>
                <mesh filename="package://motoman_gp7_support/meshes/collision/gp7_link_4_r.stl" />
            </geometry>
        </collision>
        
<inertial>
            <mass value="0.1" />
            <inertia ixx="0.03" iyy="0.03" izz="0.03" ixy="0.0" ixz="0.0" iyz="0.0" />
        </inertial>

    </link>
    <link name="link_5_b">
        <visual>
            <geometry>
                <mesh filename="package://motoman_gp7_support/meshes/visual/gp7_link_5_b.stl" />
            </geometry>
            <material name="yaskawa_blue" />
        </visual>
        <collision>
            <geometry>
                <mesh filename="package://motoman_gp7_support/meshes/collision/gp7_link_5_b.stl" />
            </geometry>
        </collision>
        
<inertial>
            <mass value="0.1" />
            <inertia ixx="0.03" iyy="0.03" izz="0.03" ixy="0.0" ixz="0.0" iyz="0.0" />
        </inertial>

    </link>
    <link name="link_6_t">
        <visual>
            <geometry>
                <mesh filename="package://motoman_gp7_support/meshes/visual/gp7_link_6_t.stl" />
            </geometry>
            <material name="yaskawa_blue" />
        </visual>
        <collision>
            <geometry>
                <mesh filename="package://motoman_gp7_support/meshes/collision/gp7_link_6_t.stl" />
            </geometry>
        </collision>
        
<inertial>
            <mass value="0.1" />
            <inertia ixx="0.03" iyy="0.03" izz="0.03" ixy="0.0" ixz="0.0" iyz="0.0" />
        </inertial>

    </link>
    <link name="tool0" />
    <!-- end of link list -->
    <!-- joint list -->
    <joint name="joint_1_s" type="revolute">
        <parent link="base_link" />
        <child link="link_1_s" />
        <origin rpy="0 0 0" xyz="0 0 0.330" />
        <axis xyz="0 0 1" />
        <limit effort="212.66" lower="-2.9670" upper="2.9670" velocity="6.5448" />
    </joint>
    <joint name="joint_2_l" type="revolute">
        <parent link="link_1_s" />
        <child link="link_2_l" />
        <origin rpy="0 0 0" xyz="0.040 0 0" />
        <axis xyz="0 1 0" />
        <limit effort="205.80" lower="-1.1344" upper="2.5307" velocity="5.4977" />
    </joint>
    <joint name="joint_3_u" type="revolute">
        <parent link="link_2_l" />
        <child link="link_3_u" />
        <origin rpy="0 0 0" xyz="0 0 0.445" />
        <axis xyz="0 -1 0" />
        <limit effort="106.82" lower="-1.2217" upper="3.3161" velocity="7.1558" />
    </joint>
    <joint name="joint_4_r" type="revolute">
        <parent link="link_3_u" />
        <child link="link_4_r" />
        <origin rpy="0 0 0" xyz="0.440 0 0.040" />
        <axis xyz="-1 0 0" />
        <limit effort="55.86" lower="-3.3161" upper="3.3161" velocity="9.5993" />
    </joint>
    <joint name="joint_5_b" type="revolute">
        <parent link="link_4_r" />
        <child link="link_5_b" />
        <origin rpy="0 0 0" xyz="0 0 0" />
        <axis xyz="0 -1 0" />
        <limit effort="32.68" lower="-2.3561" upper="2.3561" velocity="9.5993" />
    </joint>
    <joint name="joint_6_t" type="revolute">
        <parent link="link_5_b" />
        <child link="link_6_t" />
        <origin rpy="0 0 0" xyz="0 0 0" />
        <axis xyz="-1 0 0" />
        <limit effort="22.54" lower="-6.2944" upper="6.2944" velocity="17.4845" />
    </joint>
    <joint name="joint_6_t-tool0" type="fixed">
        <origin rpy="3.1415926 -1.570796 0" xyz="0.080 0 0" />
        <parent link="link_6_t" />
        <child link="tool0" />
    </joint>
    <!-- end of joint list -->
    <!-- ROS base_link to Robot Manufacturer World Coordinates transform -->
    <!--<link name="${prefix}base" />
    <joint name="${prefix}base_link-base" type="fixed">
        <origin xyz="0 0 0.330" rpy="0 0 0"/>
        <parent link="${prefix}base_link"/>
        <child link="${prefix}base"/>
    </joint>-->
    <!-- ROS base_link to Robot Manufacturer World Coordinates transform -->
    <link name="world" />
    <joint name="world_base_link" type="fixed">
        <parent link="world" />
        <child link="base_link" />
    </joint>
    <material name="Red">
        <color rgba="0.8 0.0 0.0 1.0" />
    </material>
    <joint name="joint_t0_link" type="fixed">
        <parent link="tool0" />
        <child link="gripper_t0_link" />
        <axis xyz="1 0 0" />
        <!--<origin xyz="0.0 0.0 0.0" rpy="0.0 0.0 0.0" />-->
        <origin rpy="3.14159 -1.570795 0" xyz="0.0 0.0 0.0" />
    </joint>
    <link name="gripper_t0_link">
        <visual>
            <origin rpy="0 1.570795 0" xyz="0.045 0 0" />
            <geometry>
                <cylinder length="0.09" radius="0.008" />
            </geometry>
            <material name="yaskawa_blue" />
        </visual>
        <collision>
            <origin rpy="0 1.570795 0" xyz="0.045 0 0" />
            <geometry>
                <cylinder length="0.09" radius="0.008" />
            </geometry>
        </collision>
        
<inertial>
            <mass value="0.0001" />
            <inertia ixx="1.0" ixy="0.0" ixz="0.0" iyy="0.5" iyz="0.0" izz="1.0" />
        </inertial>

    </link>
    <joint name="t0_link_tcp" type="fixed">
        <parent link="gripper_t0_link" />
        <child link="gripper_t0_tcp" />
        <axis xyz="1 0 0" />
        <origin rpy="0.0 0.0 0.0" xyz="0.09 0.0 0.0" />
    </joint>
    <link name="gripper_t0_tcp">
        <visual>
            <geometry>
                <cylinder length="0.0001" radius="0.0001" />
            </geometry>
            <origin rpy="0 0 0" xyz="0.0 0.0 0.0" />
            <material name="yaskawa_blue" />
        </visual>
        
<inertial>
            <mass value="0.0001" />
            <inertia ixx="1.0" ixy="0.0" ixz="0.0" iyy="0.5" iyz="0.0" izz="1.0" />
        </inertial>

        <collision>
            <geometry>
                <cylinder length="0.0001" radius="0.0001" />
            </geometry>
            <origin rpy="0 0 0" xyz="0.0 0.0 0.0" />
        </collision>
    </link>
    
<transmission name="trans_joint_1_s">
        <type>transmission_interface/SimpleTransmission</type>
        <joint name="joint_1_s">
            <hardwareInterface>hardware_interface/EffortJointInterface</hardwareInterface>
        </joint>
        <actuator name="joint_1_s_motor">
            <hardwareInterface>hardware_interface/EffortJointInterface</hardwareInterface>
            <mechanicalReduction>1</mechanicalReduction>
        </actuator>
    </transmission>
    <transmission name="trans_joint_2_l">
        <type>transmission_interface/SimpleTransmission</type>
        <joint name="joint_2_l">
            <hardwareInterface>hardware_interface/EffortJointInterface</hardwareInterface>
        </joint>
        <actuator name="joint_2_l_motor">
            <hardwareInterface>hardware_interface/EffortJointInterface</hardwareInterface>
            <mechanicalReduction>1</mechanicalReduction>
        </actuator>
    </transmission>
    <transmission name="trans_joint_3_u">
        <type>transmission_interface/SimpleTransmission</type>
        <joint name="joint_3_u">
            <hardwareInterface>hardware_interface/EffortJointInterface</hardwareInterface>
        </joint>
        <actuator name="joint_3_u_motor">
            <hardwareInterface>hardware_interface/EffortJointInterface</hardwareInterface>
            <mechanicalReduction>1</mechanicalReduction>
        </actuator>
    </transmission>
    <transmission name="trans_joint_4_r">
        <type>transmission_interface/SimpleTransmission</type>
        <joint name="joint_4_r">
            <hardwareInterface>hardware_interface/EffortJointInterface</hardwareInterface>
        </joint>
        <actuator name="joint_4_r_motor">
            <hardwareInterface>hardware_interface/EffortJointInterface</hardwareInterface>
            <mechanicalReduction>1</mechanicalReduction>
        </actuator>
    </transmission>
    <transmission name="trans_joint_5_b">
        <type>transmission_interface/SimpleTransmission</type>
        <joint name="joint_5_b">
            <hardwareInterface>hardware_interface/EffortJointInterface</hardwareInterface>
        </joint>
        <actuator name="joint_5_b_motor">
            <hardwareInterface>hardware_interface/EffortJointInterface</hardwareInterface>
            <mechanicalReduction>1</mechanicalReduction>
        </actuator>
    </transmission>
    <transmission name="trans_joint_6_t">
        <type>transmission_interface/SimpleTransmission</type>
        <joint name="joint_6_t">
            <hardwareInterface>hardware_interface/EffortJointInterface</hardwareInterface>
        </joint>
        <actuator name="joint_6_t_motor">
            <hardwareInterface>hardware_interface/EffortJointInterface</hardwareInterface>
            <mechanicalReduction>1</mechanicalReduction>
        </actuator>
    </transmission>
    <gazebo>
        <plugin name="gazebo_ros_control" filename="libgazebo_ros_control.so">
            <robotNamespace>/</robotNamespace>
        </plugin>
    </gazebo>
</robot>
